Workbook

Sheet Yapılacaklar
A1: KV260 3D GPU — Yapılacaklar Listesi
A2: ID | B2: Faz | C2: Görev | D2: Detay / açıklama | E2: Kategori | F2: Öncelik | G2: Tahmini | H2: Bağımlılık | I2: Durum | J2: Not
A3: F0-1 | B3: Faz 0 | C3: Araç zinciri kurulumu | D3: Vivado + Vitis + PetaLinux (uyumlu sürüm) makineye kur; lisans/erişim doğrula | E3: Platform/Kurulum | F3: Yüksek | G3: 1 gün | I3: Yapılacak
A4: F0-2 | B4: Faz 0 | C4: Ubuntu image flash & boot | D4: Certified Ubuntu for Kria SD image'ini indir, flash et, KV260'ı boot et | E4: Platform/Kurulum | F4: Yüksek | G4: 0.5 gün | H4: F0-1 | I4: Yapılacak
A5: F0-3 | B5: Faz 0 | C5: İlk boot doğrulama | D5: UART console + Ethernet/SSH erişimi; sistem sağlığı kontrolü | E5: Platform/Kurulum | F5: Yüksek | G5: 0.5 gün | H5: F0-2 | I5: Yapılacak
A6: F0-4 | B6: Faz 0 | C6: HDMI test pattern (DRM/KMS) | D6: modetest ile bir framebuffer'ı HDMI'dan ekrana bastır | E6: Video/HDMI | F6: Yüksek | G6: 1 gün | H6: F0-3 | I6: Yapılacak | J6: En kritik erken kanıt
A7: F0-5 | B7: Faz 0 | C7: Minimal PL AXI-Lite peripheral | D7: Vivado block design: bir register bloğu (AXI-Lite slave) sentezle | E7: Donanım (PL) | F7: Yüksek | G7: 1 gün | H7: F0-1 | I7: Yapılacak
A8: F0-6 | B8: Faz 0 | C8: Bitstream'i Kria app olarak yükle | D8: fpga-manager/xmutil + device-tree overlay ile PL tasarımını Linux'a bağla | E8: Platform/Kurulum | F8: Yüksek | G8: 1-2 gün | H8: F0-5, F0-2 | I8: Yapılacak | J8: Kria'ya özel akış
A9: F0-7 | B9: Faz 0 | C9: PS↔PL register erişimi | D9: ARM'dan AXI-Lite register oku/yaz (devmem / basit C); PS↔PL hattı kanıtı | E9: Test/Doğrulama | F9: Yüksek | G9: 0.5 gün | H9: F0-6 | I9: Yapılacak
A10: F0-8 | B10: Faz 0 | C10: Simülasyon ortamı | D10: Verilator + cocotb kur; minimal testbench koştur | E10: Test/Doğrulama | F10: Yüksek | G10: 1 gün | H10: F0-1 | I10: Yapılacak
A11: F0-9 | B11: Faz 0 | C11: Repo & proje iskeleti | D11: Git repo, dizin yapısı (rtl/ sw/ sim/ docs/), README | E11: Platform/Kurulum | F11: Orta | G11: 0.5 gün | I11: Yapılacak
A12: F1-1 | B12: Faz 1 | C12: Vektör/matris kütüphanesi | D12: vec3/vec4/mat4; MVP, perspective, lookAt yardımcıları (C) | E12: Yazılım (PS) | F12: Yüksek | G12: 1 gün | H12: F0-9 | I12: Yapılacak
A13: F1-2 | B13: Faz 1 | C13: Geometri yükleme | D13: Hardcoded küp + basit OBJ okuyucu (vertex + UV + normal) | E13: Yazılım (PS) | F13: Orta | G13: 1 gün | H13: F1-1 | I13: Yapılacak
A14: F1-3 | B14: Faz 1 | C14: Transform + viewport (SW) | D14: MVP → clip → perspective divide → NDC → ekran koordinatı | E14: Yazılım (PS) | F14: Yüksek | G14: 1 gün | H14: F1-1 | I14: Yapılacak
A15: F1-4 | B15: Faz 1 | C15: Edge-function rasterizer (SW) | D15: Bounding box + edge-function kapsama, yazılımda | E15: Yazılım (PS) | F15: Yüksek | G15: 1-2 gün | H15: F1-3 | I15: Yapılacak
A16: F1-5 | B16: Faz 1 | C16: Perspektif-doğru interpolasyon (SW) | D16: Barycentric + 1/w ile u, v, z, ışık | E16: Yazılım (PS) | F16: Yüksek | G16: 1 gün | H16: F1-4 | I16: Yapılacak
A17: F1-6 | B17: Faz 1 | C17: Doku örnekleme (nearest, SW) | D17: Texel fetch + modülasyon | E17: Yazılım (PS) | F17: Orta | G17: 0.5 gün | H17: F1-5 | I17: Yapılacak
A18: F1-7 | B18: Faz 1 | C18: Gouraud diffuse ışık (SW) | D18: Köşe ışığı + interpolasyon | E18: Yazılım (PS) | F18: Orta | G18: 0.5 gün | H18: F1-5 | I18: Yapılacak
A19: F1-8 | B19: Faz 1 | C19: Z-buffer (SW) | D19: Derinlik testi | E19: Yazılım (PS) | F19: Yüksek | G19: 0.5 gün | H19: F1-4 | I19: Yapılacak
A20: F1-9 | B20: Faz 1 | C20: DRM framebuffer'a çizim | D20: Yazılım renderer çıktısını HDMI'a bastır | E20: Video/HDMI | F20: Yüksek | G20: 1 gün | H20: F1-4, F0-4 | I20: Yapılacak
A21: F1-10 | B21: Faz 1 | C21: Kamera + input (evdev) | D21: Klavye/gamepad ile gezilebilir sahne (yazılım) | E21: Yazılım (PS) | F21: Orta | G21: 1 gün | H21: F1-9 | I21: Yapılacak
A22: F1-11 | B22: Faz 1 | C22: Golden model dump | D22: Referans piksel/attribute çıktısı — donanım karşılaştırması için | E22: Test/Doğrulama | F22: Yüksek | G22: 0.5 gün | H22: F1-5 | I22: Yapılacak | J22: Tüm HW doğrulamalarının temeli
A23: F2-1 | B23: Faz 2 | C23: DDR4 framebuffer bölgesi | D23: PS'te bellek ayır (CMA/reserved-mem), fiziksel adresi PL'e paylaş | E23: Bellek/DDR4 | F23: Yüksek | G23: 1 gün | H23: F0-7 | I23: Yapılacak
A24: F2-2 | B24: Faz 2 | C24: PL AXI master (HP) yazma | D24: DDR4'e burst-write yapan AXI master modülü | E24: Donanım (PL) | F24: Yüksek | G24: 2-3 gün | H24: F0-5 | I24: Yapılacak
A25: F2-3 | B25: Faz 2 | C25: PL test pattern yazma | D25: PL framebuffer'a bir desen yazsın | E25: Donanım (PL) | F25: Orta | G25: 0.5 gün | H25: F2-2, F2-1 | I25: Yapılacak
A26: F2-4 | B26: Faz 2 | C26: DRM scanout entegrasyonu | D26: O framebuffer'ı DRM/KMS ile tara | E26: Video/HDMI | F26: Yüksek | G26: 1 gün | H26: F2-3, F1-9 | I26: Yapılacak
A27: F2-5 | B27: Faz 2 | C27: PL→DDR4→HDMI doğrulama | D27: Uçtan uca yol kanıtı | E27: Test/Doğrulama | F27: Yüksek | G27: 0.5 gün | H27: F2-4 | I27: Yapılacak
A28: F2-6 | B28: Faz 2 | C28: AXI master simülasyonu | D28: cocotb + AXI model ile master'ı doğrula | E28: Test/Doğrulama | F28: Orta | G28: 1 gün | H28: F2-2, F0-8 | I28: Yapılacak
A29: F3-1 | B29: Faz 3 | C29: Fixed-point (Q16.16) altyapı | D29: Format, yardımcılar, taşma/aralık analizi | E29: Donanım (PL) | F29: Yüksek | G29: 1 gün | I29: Yapılacak
A30: F3-2 | B30: Faz 3 | C30: Triangle setup modülü | D30: Edge katsayıları + bounding box | E30: Donanım (PL) | F30: Yüksek | G30: 1-2 gün | H30: F3-1 | I30: Yapılacak
A31: F3-3 | B31: Faz 3 | C31: Edge-function evaluator | D31: İnkremental adder tabanlı kapsama testi | E31: Donanım (PL) | F31: Yüksek | G31: 1-2 gün | H31: F3-2 | I31: Yapılacak
A32: F3-4 | B32: Faz 3 | C32: Bbox iterator FSM | D32: Piksel tarama kontrolü | E32: Donanım (PL) | F32: Yüksek | G32: 1 gün | H32: F3-3 | I32: Yapılacak
A33: F3-5 | B33: Faz 3 | C33: Flat renk + fb writer bağlama | D33: Düz renkli fragment → framebuffer | E33: Donanım (PL) | F33: Orta | G33: 1 gün | H33: F3-4, F2-2 | I33: Yapılacak
A34: F3-6 | B34: Faz 3 | C34: Komut buffer (minimal) | D34: PS ekran-uzayı üçgeni beslesin | E34: Yazılım (PS) | F34: Orta | G34: 1 gün | H34: F0-7 | I34: Yapılacak
A35: F3-7 | B35: Faz 3 | C35: İlk üçgen doğrulama | D35: cocotb + golden model karşılaştırma | E35: Test/Doğrulama | F35: Yüksek | G35: 1 gün | H35: F3-5, F1-11 | I35: Yapılacak | J35: İlk donanım üçgeni — milestone
A36: F4-1 | B36: Faz 4 | C36: Interpolator modülü | D36: Barycentric + 1/w + attr/w | E36: Donanım (PL) | F36: Yüksek | G36: 2 gün | H36: F3-4 | I36: Yapılacak
A37: F4-2 | B37: Faz 4 | C37: Per-pixel reciprocal | D37: Pipelined divider / Newton-Raphson | E37: Donanım (PL) | F37: Yüksek | G37: 1-2 gün | H37: F4-1 | I37: Yapılacak
A38: F4-3 | B38: Faz 4 | C38: Texture unit — adresleme | D38: UV → texel adresi | E38: Donanım (PL) | F38: Orta | G38: 1 gün | H38: F4-1 | I38: Yapılacak
A39: F4-4 | B39: Faz 4 | C39: Texture cache (BRAM/URAM) | D39: On-chip cache + miss'te AXI fetch | E39: Donanım (PL) | F39: Yüksek | G39: 2-3 gün | H39: F4-3, F2-2 | I39: Yapılacak
A40: F4-5 | B40: Faz 4 | C40: Nearest sampling | D40: Texel örnekleme | E40: Donanım (PL) | F40: Orta | G40: 0.5 gün | H40: F4-4 | I40: Yapılacak
...

Sheet Özet
A1: Özet ve İlerleme
A2: Nasıl kullanılır: 'Yapılacaklar' sekmesinde düzenlenecek sütunlar → Durum (açılır liste) ve Not. Durum seçenekleri: Yapılacak · Devam ediyor · Bloke · Tamam. Diğer sütunlar plandır. Süreler kabaca tahmindir.
A4: Toplam görev | B4: =COUNTA(Yapılacaklar!A3:A65) -> 63
A5: Tamam | B5: =COUNTIF(Yapılacaklar!I3:I65,"Tamam") -> 0
A6: Devam ediyor | B6: =COUNTIF(Yapılacaklar!I3:I65,"Devam ediyor") -> 0
A7: Bloke | B7: =COUNTIF(Yapılacaklar!I3:I65,"Bloke") -> 0
A8: Yapılacak | B8: =COUNTIF(Yapılacaklar!I3:I65,"Yapılacak") -> 63
A9: Tamamlanma % | B9: =IFERROR(B5/B4,0) -> 0
A11: Faz | B11: Tema | C11: Toplam | D11: Tamam | E11: %
A12: Faz 0 | B12: Platform bring-up | C12: =COUNTIF(Yapılacaklar!B3:B65,"Faz 0") -> 9 | D12: =COUNTIFS(Yapılacaklar!B3:B65,"Faz 0",Yapılacaklar!I3:I65,"Tamam") -> 0 | E12: =IFERROR(D12/C12,0) -> 0
A13: Faz 1 | B13: Yazılım referans renderer (golden model) | C13: =COUNTIF(Yapılacaklar!B3:B65,"Faz 1") -> 11 | D13: =COUNTIFS(Yapılacaklar!B3:B65,"Faz 1",Yapılacaklar!I3:I65,"Tamam") -> 0 | E13: =IFERROR(D13/C13,0) -> 0
A14: Faz 2 | B14: PL → DDR4 → HDMI yolu | C14: =COUNTIF(Yapılacaklar!B3:B65,"Faz 2") -> 6 | D14: =COUNTIFS(Yapılacaklar!B3:B65,"Faz 2",Yapılacaklar!I3:I65,"Tamam") -> 0 | E14: =IFERROR(D14/C14,0) -> 0
A15: Faz 3 | B15: PL 2D üçgen rasterizer (flat) | C15: =COUNTIF(Yapılacaklar!B3:B65,"Faz 3") -> 7 | D15: =COUNTIFS(Yapılacaklar!B3:B65,"Faz 3",Yapılacaklar!I3:I65,"Tamam") -> 0 | E15: =IFERROR(D15/C15,0) -> 0
A16: Faz 4 | B16: Perspektif-doğru + doku | C16: =COUNTIF(Yapılacaklar!B3:B65,"Faz 4") -> 6 | D16: =COUNTIFS(Yapılacaklar!B3:B65,"Faz 4",Yapılacaklar!I3:I65,"Tamam") -> 0 | E16: =IFERROR(D16/C16,0) -> 0
A17: Faz 5 | B17: Z-buffer + depth cache | C17: =COUNTIF(Yapılacaklar!B3:B65,"Faz 5") -> 4 | D17: =COUNTIFS(Yapılacaklar!B3:B65,"Faz 5",Yapılacaklar!I3:I65,"Tamam") -> 0 | E17: =IFERROR(D17/C17,0) -> 0
A18: Faz 6 | B18: Işık + fragment shading | C18: =COUNTIF(Yapılacaklar!B3:B65,"Faz 6") -> 4 | D18: =COUNTIFS(Yapılacaklar!B3:B65,"Faz 6",Yapılacaklar!I3:I65,"Tamam") -> 0 | E18: =IFERROR(D18/C18,0) -> 0
A19: Faz 7 | B19: Geometry aşaması PL'e (tam GPU) | C19: =COUNTIF(Yapılacaklar!B3:B65,"Faz 7") -> 7 | D19: =COUNTIFS(Yapılacaklar!B3:B65,"Faz 7",Yapılacaklar!I3:I65,"Tamam") -> 0 | E19: =IFERROR(D19/C19,0) -> 0
A20: Faz 8 | B20: Oyun + double-buffer + optimizasyon | C20: =COUNTIF(Yapılacaklar!B3:B65,"Faz 8") -> 9 | D20: =COUNTIFS(Yapılacaklar!B3:B65,"Faz 8",Yapılacaklar!I3:I65,"Tamam") -> 0 | E20: =IFERROR(D20/C20,0) -> 0
A21: Toplam | C21: =SUM(C12:C20) -> 63 | D21: =SUM(D12:D20) -> 0 | E21: =IFERROR(D21/C21,0) -> 0

Sheet Fazlar
A1: Faz Milestone'ları
A2: Faz | B2: Tema | C2: Hedef çıktı (milestone) | D2: Durum
A3: Faz 0 | B3: Platform bring-up | C3: Ubuntu + HDMI test pattern; AXI hello-world; sim ortamı hazır | D3: Yapılacak
A4: Faz 1 | B4: Yazılım referans renderer | C4: Tüm pipeline C'de → HDMI (golden model); gezilebilir sahne (SW) | D4: Yapılacak
A5: Faz 2 | B5: PL → DDR4 → HDMI | C5: PL framebuffer'a yazar, DRM tarar; uçtan uca video yolu kanıtlı | D5: Yapılacak
A6: Faz 3 | B6: PL 2D rasterizer | C6: Edge-function core; donanımda ilk (flat) üçgen | D6: Yapılacak
A7: Faz 4 | B7: Perspektif-doğru + doku | C7: Interpolasyon + texture unit/cache; dokulu üçgen | D7: Yapılacak
A8: Faz 5 | B8: Z-buffer | C8: Depth unit + cache; doğru occlusion | D8: Yapılacak
A9: Faz 6 | B9: Işık + shading | C9: Gouraud ışık; tam ışıklı-dokulu fragment | D9: Yapılacak
A10: Faz 7 | B10: Geometry PL'e | C10: MVP + persp divide + clip + cull donanımda; tam GPU | D10: Yapılacak
A11: Faz 8 | B11: Oyun + optimizasyon | C11: Double-buffer, IRQ, oyun döngüsü, tuning; gezilebilir mini oyun @ hedef FPS | D11: Yapılacak
